Workbook

Sheet קרא_אותי
A1: תבנית תיק מטופל — גרסה 2
A2: תיק המקרה מכיל עובדות בלבד ומקושר למסד הבסיס. אין לבנות מילון ניסוחים; ה-AI מבין את שאלת התלמיד ומחזיר תשובה טבעית וממוקדת.
A4: נושא | B4: הנחיה
A5: סדר עבודה | B5: לאשר תחילה סיפור קליני, אחר כך למלא את כל מזהי הבסיס ולבסוף רובריקות ובקרת איכות.
A6: שפה חופשית | B6: ה-AI מפרש משמעות רפואית, שגיאות כתיב, מילים נרדפות ושאלות רחבות.
A7: מענה מטופל | B7: לענות רק למה שנשאל; אין לנדב מידע רפואי נוסף.
A8: עובדה חסרה | B8: אם הכוונה ברורה אך המידע אינו בתיק: לא ידוע לי / איני זוכר.
A9: עולם סגור | B9: אין להמציא עובדות; מותר לנסח מחדש עובדה מאושרת באופן טבעי.
A10: בדיקות דם | B10: כל ערך מספרי כולל יחידה וטווח ייחוס של אותה מעבדה.
A11: בדיקות המשך | B11: לפני מסירת תוצאות התלמיד מחליט מה לעשות כעת; אחר כך מוצג שחלף שבוע.
A12: PDF ביניים | B12: בכל שלב ניתן להפיק PDF הכולל את כל המידע והמשוב שנצברו עד אותה נקודה.
A13: רמות חשיבות | B13: חיוני במקרה / חשוב / משלים / בדרך כלל לא מרכזי בלבד.
A14: אישור | B14: כל הבדיקות מאושרות בפיילוט; תנאי אישור עתידיים אינם פעילים.
A15: מקור אמת מספרי | B15: ערכי מטופל, יחידות וטווחים מוזנים רק בגיליון תוצאות_מספריות; בדיקות_מיידיות מכיל הגדרה ופרשנות בלבד.

Sheet מטא_מקרה
A1: מטא-נתונים ופתיחת המקרה
A2: רק נוסח הפתיחה נחשף אוטומטית לתלמיד; יתר השדות פנימיים.
A4: שדה | B4: ערך
A5: מזהה מקרה | B5: CASE-004
A6: שיוך למסד המחלות | B6: אין שיוך במסד הכללי (מקרה חדש)
A7: אבחנה ידועה למערכת | B7: אי־ספיקת לב דו־צדדית המתגלית לראשונה, עם החמרה חריפה על רקע פגיעה כרונית בשריר הלב לאחר אוטם קודם; HFrEF, EF 32%.
A8: ראשי תיבות מטופל | B8: א.ק.
A9: גיל | B9: 70
A10: מין | B10: גבר
A11: מצב בזמן הכניסה | B11: ערני ומתמצא, חרד וקצר נשימה, יושב זקוף ומתקשה לשכב; מצב יציב מבחינת זילוח, אך זקוק להערכה וטיפול דחופים ולאשפוז.
A12: נוסח פתיחה לתלמיד | B12: א.ק., גבר בן 70, הגיע בשל קושי בנשימה המחמיר במיוחד בלילה ובשכיבה.
A13: אמת קלינית | B13: אי־ספיקת לב דו־צדדית עם ירידה בתפקוד הסיסטולי של חדר שמאל (EF 32%) ופגיעה בתפקוד חדר ימין, המאובחנת לראשונה כעת ומוחמרת בימים האחרונים. ברקע אוטם לפני עשור שטופל בצנתור ובתומכן פתוח, יתר לחץ דם, סוכרת, הפרעה בשומני הדם, השמנה, עישון והיענות לא עקבית לטיפול. גודש ריאתי (אורתופנאה, התעוררות לילית, חרחורים, סטורציה 90%) וגודש סיסטמי (JVP, בצקות, כבד מוגדל); ללא הלם קרדיוגני וללא ראיה מספקת לאוטם חדש. דרוש אשפוז, ניטור, טיפול בגודש ומשטר תרופתי לפי החומר הנלמד.
A14: מטרת למידה | B14: לזהות אי־ספיקת לב שמאלית וימנית מן הסיפור והממצאים; להבחין בין סימני גודש ריאתי ומערכתי; לבחור בדיקות רלוונטיות, לפרש אקו EF 32% ולתכנן אשפוז, טיפול ומעקב.
A15: מצב דינמי | B15: אין שינוי במהלך הקבלה, אלא אם אושר אחרת
A16: אישור בדיקות בפיילוט | B16: כל הבדיקות מאושרות; מידתיותן נבחנת במשוב
A17: משך שמירה | B17: 14
A18: יחידת משך שמירה | B18: ימים
A19: גרסת תיק | B19: 0.1
A20: סטטוס | B20: מאושר לבניית אב-טיפוס
A21: מנוע שיחה | B21: AI סמנטי לפי מדיניות_AI במסד הבסיס
A22: מענה יזום | B22: אין לנדב מידע שלא נשאל
A23: נקודת החלטה לפני המשך | B23: חובה לפני הצגת תוצאות בדיקות ההמשך
A24: PDF ביניים | B24: זמין בכל שלב עם משוב עד כה
A25: גרסת תבנית | B25: 2.1
A26: פרסונה קצרה | B26: רואה חשבון בגמלאות, יליד משפחה עיראקית, נשוי וסב לשני נכדים. חברותי, פטפטן, חרד ודואג לחזור לבית החולים; לפעמים סוטה לסיפורים על אשתו, מאפים, נכדיו ועבודתו, אך עונה לעניין. מדבר עברית יומיומית ולא מונחים מקצועיים; אינו מקפיד תמיד על נטילת התרופות ועל המלצות אורח חיים. כאשר הוא קצר נשימה משפטיו מתקצרים.

Sheet אנמנזה
A1: תבנית אנמנזה
A2: כל 89 מזהי האנמנזה קיימים. מלאו תשובה בגוף ראשון, חשיבות והיגיון.
A4: מזהה ערך בתיק | B4: מזהה רכיב בסיס | C4: כוונת הבירור | D4: תשובת המטופל | E4: חשיבות במקרה | F4: היגיון למשוב | G4: סטטוס | H4: הערות הפעלה
A5: CASE-004-AN-001 | B5: AN-001 | C5: גיל | D5: אני בן שבעים, מי היה מאמין. מרגיש לפעמים מבוגר בעשר שנים ממה שכתוב בתעודה. | E5: משלים | F5: בירור גיל עשוי להוסיף הקשר, אך אינו מרכזי לזיהוי סיבת קוצר הנשימה במקרה זה. | G5: מאושר | H5: לענות רק למה שנשאל; מותר לנסח באופן טבעי בלי להוסיף עובדות.
A6: CASE-004-AN-002 | B6: AN-002 | C6: מין | D6: אני זכר, כן. עכשיו עם הנשימה הזאת אני בעיקר דואג. | E6: משלים | F6: בירור מין עשוי להוסיף הקשר, אך אינו מרכזי לזיהוי סיבת קוצר הנשימה במקרה זה. | G6: מאושר | H6: לענות רק למה שנשאל; מותר לנסח באופן טבעי בלי להוסיף עובדות.
A7: CASE-004-AN-003 | B7: AN-003 | C7: מוצא | D7: המשפחה שלי במקור מעיראק; גדלתי כאן, והבית שלנו תמיד היה מלא אנשים ואוכל. | E7: משלים | F7: בירור מוצא עשוי להוסיף הקשר, אך אינו מרכזי לזיהוי סיבת קוצר הנשימה במקרה זה. | G7: מאושר | H7: לענות רק למה שנשאל; מותר לנסח באופן טבעי בלי להוסיף עובדות.
A8: CASE-004-AN-004 | B8: AN-004 | C8: מצב משפחתי ותמיכה בבית | D8: אני נשוי, אשתי איתי בבית. יש לנו שני ילדים ושני נכדים; הבת מתקשרת כל ערב לבדוק אותי. | E8: משלים | F8: בירור מצב משפחתי ותמיכה בבית עשוי להוסיף הקשר, אך אינו מרכזי לזיהוי סיבת קוצר הנשימה במקרה זה. | G8: מאושר | H8: לענות רק למה שנשאל; מותר לנסח באופן טבעי בלי להוסיף עובדות.
A9: CASE-004-AN-005 | B9: AN-005 | C9: מקצוע ואופי העבודה | D9: הייתי רואה חשבון כל החיים, ישבתי שעות במשרד. מאז שפרשתי אני בעיקר בבית. | E9: בדרך כלל לא מרכזי | F9: בירור מקצוע ואופי העבודה עשוי להוסיף הקשר, אך אינו מרכזי לזיהוי סיבת קוצר הנשימה במקרה זה. | G9: מאושר | H9: לענות רק למה שנשאל; מותר לנסח באופן טבעי בלי להוסיף עובדות.
A10: CASE-004-AN-006 | B10: AN-006 | C10: הסיבה שבגללה הגיע כעת | D10: לא הצלחתי לנשום בלילה, כאילו אין לי מספיק אוויר. אשתי אמרה שהפעם לא מתווכחים ונוסעים. | E10: חיוני במקרה | F10: בירור הסיבה שבגללה הגיע כעת מסייע לזהות את חומרת קוצר הנשימה, הגודש או הרקע הלבבי, ולכן משמעותי בקבלת ההחלטות. | G10: מאושר | H10: לענות רק למה שנשאל; מותר לנסח באופן טבעי בלי להוסיף עובדות.
A11: CASE-004-AN-007 | B11: AN-007 | C11: התסמין הדומיננטי | D11: הבעיה העיקרית היא הנשימה, במיוחד כשאני מנסה לשכב לישון. | E11: חיוני במקרה | F11: בירור התסמין הדומיננטי מסייע לזהות את חומרת קוצר הנשימה, הגודש או הרקע הלבבי, ולכן משמעותי בקבלת ההחלטות. | G11: מאושר | H11: לענות רק למה שנשאל; מותר לנסח באופן טבעי בלי להוסיף עובדות.
A12: CASE-004-AN-008 | B12: AN-008 | C12: מדוע פנה דווקא עכשיו | D12: בשלושת הימים האחרונים אני מתעורר שוב ושוב ונחנק. זה ממש הפחיד אותי. | E12: חיוני במקרה | F12: בירור מדוע פנה דווקא עכשיו מסייע לזהות את חומרת קוצר הנשימה, הגודש או הרקע הלבבי, ולכן משמעותי בקבלת ההחלטות. | G12: מאושר | H12: לענות רק למה שנשאל; מותר לנסח באופן טבעי בלי להוסיף עובדות.
A13: CASE-004-AN-009 | B13: AN-009 | C13: מועד תחילת התסמין | D13: לפני כמה שבועות התחיל להיות לי קשה לעלות מדרגות; בלילות האחרונים זה הרבה יותר גרוע. | E13: חיוני במקרה | F13: בירור מועד תחילת התסמין מסייע לזהות את חומרת קוצר הנשימה, הגודש או הרקע הלבבי, ולכן משמעותי בקבלת ההחלטות. | G13: מאושר | H13: לענות רק למה שנשאל; מותר לנסח באופן טבעי בלי להוסיף עובדות.
A14: CASE-004-AN-010 | B14: AN-010 | C14: התחלה פתאומית או הדרגתית | D14: בהתחלה זה הגיע לאט, אבל בימים האחרונים החמיר ממש. | E14: חיוני במקרה | F14: בירור התחלה פתאומית או הדרגתית מסייע לזהות את חומרת קוצר הנשימה, הגודש או הרקע הלבבי, ולכן משמעותי בקבלת ההחלטות. | G14: מאושר | H14: לענות רק למה שנשאל; מותר לנסח באופן טבעי בלי להוסיף עובדות.
A15: CASE-004-AN-011 | B15: AN-011 | C15: מיקום התסמין | D15: זה לא כאב בנקודה מסוימת; זו תחושה שבית החזה לא מקבל אוויר. | E15: משלים | F15: בירור מיקום התסמין עשוי להוסיף הקשר, אך אינו מרכזי לזיהוי סיבת קוצר הנשימה במקרה זה. | G15: מאושר | H15: לענות רק למה שנשאל; מותר לנסח באופן טבעי בלי להוסיף עובדות.
... A93: CASE-004-AN-089 | B93: AN-089 | C93: חום, שיעול או מחלה נשימתית | D93: אין חום, אין צמרמורות ואין ליחה מוגלתית; רק שיעול קל בעיקר בלילה. | E93: חשוב | F93: בירור חום, שיעול או מחלה נשימתית משלים את הערכת גורמי הסיכון, מחלות הרקע, האבחנה המבדלת או התפקוד היומיומי. | G93: מאושר | H93: לענות רק למה שנשאל; מותר לנסח באופן טבעי בלי להוסיף עובדות.

Sheet בדיקה_גופנית
A1: תבנית בדיקה גופנית
A2: כל 45 מזהי הבדיקה קיימים. מלאו ממצא קבוע, חשיבות והיגיון.
A4: מזהה ערך בתיק | B4: מזהה רכיב בסיס | C4: רכיב בדיקה | D4: ממצא במקרה | E4: חשיבות במקרה | F4: היגיון למשוב | G4: סטטוס | H4: הערות הפעלה
A5: CASE-004-PE-001 | B5: PE-001 | C5: מראה כללי וסימני מצוקה | D5: בהכרה מלאה, חרד, במצוקה נשימתית בינונית, יושב זקוף. | E5: חיוני במקרה | F5: הממצא בתחום מראה כללי וסימני מצוקה מסייע להעריך גודש, חמצון או חומרת אי־ספיקת הלב. | G5: מאושר | H5: ממצא קבוע בתיק המטופל.
A6: CASE-004-PE-002 | B6: PE-002 | C6: מצב הכרה והתמצאות | D6: ערני, מתמצא בזמן, במקום ובאדם, עונה לעניין. | E6: חיוני במקרה | F6: הממצא בתחום מצב הכרה והתמצאות מסייע להעריך גודש, חמצון או חומרת אי־ספיקת הלב. | G6: מאושר | H6: ממצא קבוע בתיק המטופל.
A7: CASE-004-PE-003 | B7: PE-003 | C7: תנוחת המטופל ויכולת לדבר | D7: מעדיף ישיבה זקופה, מדבר במשפטים קצרים בשל קוצר נשימה. | E7: חיוני במקרה | F7: הממצא בתחום תנוחת המטופל ויכולת לדבר מסייע להעריך גודש, חמצון או חומרת אי־ספיקת הלב. | G7: מאושר | H7: ממצא קבוע בתיק המטופל.
A8: CASE-004-PE-004 | B8: PE-004 | C8: מבנה גוף ומצב תזונתי | D8: השמנה; BMI 31.4. | E8: חשוב | F8: הממצא בתחום מבנה גוף ומצב תזונתי מוסיף מידע לבדיקת מצב המטופל ולאבחנה מבדלת. | G8: מאושר | H8: ממצא קבוע בתיק המטופל.
A9: CASE-004-PE-005 | B9: PE-005 | C9: קצב הדופק | D9: דופק 108 פעימות בדקה. | E9: חיוני במקרה | F9: הממצא בתחום קצב הדופק מסייע להעריך גודש, חמצון או חומרת אי־ספיקת הלב. | G9: מאושר | H9: ממצא קבוע בתיק המטופל.
A10: CASE-004-PE-006 | B10: PE-006 | C10: סדירות הדופק | D10: דופק סדיר. | E10: חשוב | F10: הממצא בתחום סדירות הדופק מוסיף מידע לבדיקת מצב המטופל ולאבחנה מבדלת. | G10: מאושר | H10: ממצא קבוע בתיק המטופל.
A11: CASE-004-PE-007 | B11: PE-007 | C11: עוצמת הדופק | D11: דופק פריפרי מורגש, מעט חלש אך אינו חוטי. | E11: חשוב | F11: הממצא בתחום עוצמת הדופק מוסיף מידע לבדיקת מצב המטופל ולאבחנה מבדלת. | G11: מאושר | H11: ממצא קבוע בתיק המטופל.
A12: CASE-004-PE-008 | B12: PE-008 | C12: השוואת דפקים בין הצדדים | D12: דפקים דומים בשני הצדדים. | E12: משלים | F12: הבדיקה של השוואת דפקים בין הצדדים משלימה את הבדיקה הגופנית ואינה ראיה מרכזית לאי־ספיקת הלב. | G12: מאושר | H12: ממצא קבוע בתיק המטופל.
A13: CASE-004-PE-009 | B13: PE-009 | C13: לחץ דם | D13: 148/88 ממ"כ. | E13: חיוני במקרה | F13: הממצא בתחום לחץ דם מסייע להעריך גודש, חמצון או חומרת אי־ספיקת הלב. | G13: מאושר | H13: ממצא קבוע בתיק המטופל.
A14: CASE-004-PE-010 | B14: PE-010 | C14: מספר הנשימות | D14: 26 נשימות בדקה. | E14: חיוני במקרה | F14: הממצא בתחום מספר הנשימות מסייע להעריך גודש, חמצון או חומרת אי־ספיקת הלב. | G14: מאושר | H14: ממצא קבוע בתיק המטופל.
A15: CASE-004-PE-011 | B15: PE-011 | C15: אופי ודפוס הנשימה | D15: נשימה מהירה ושטחית יחסית, מוחמרת בשכיבה. | E15: חיוני במקרה | F15: הממצא בתחום אופי ודפוס הנשימה מסייע להעריך גודש, חמצון או חומרת אי־ספיקת הלב. | G15: מאושר | H15: ממצא קבוע בתיק המטופל.
... A49: CASE-004-PE-045 | B49: PE-045 | C49: רפלקסים גידיים | D49: רפלקסים גידיים תקינים וסימטריים. | E49: בדרך כלל לא מרכזי | F49: הבדיקה של רפלקסים גידיים משלימה את הבדיקה הגופנית ואינה ראיה מרכזית לאי־ספיקת הלב. | G49: מאושר | H49: ממצא קבוע בתיק המטופל.

Sheet בדיקות_מיידיות
A1: תבנית בדיקות מיידיות
A2: הגדרה, ממצא מילולי ופרשנות בלבד. כל ערך מספרי, יחידה וטווח ייחוס נלקחים בלעדית מתוצאות_מספריות.
A4: מזהה ערך בתיק | B4: מזהה רכיב בסיס | C4: בדיקה או רכיב | D4: תוצאה להצגה | E4: ערך מספרי — לא להזנה | F4: יחידה — לא להזנה | G4: טווח ייחוס — לא להזנה | H4: פרשנות במקרה | I4: חשיבות במקרה | J4: היגיון למשוב | K4: סטטוס
A5: CASE-004-IT-001 | B5: IT-001 | C5: גובה | D5: נוצר אוטומטית מתוצאות_מספריות. | H5: גובה 174 ס"מ. | I5: משלים | J5: נתון לתיאור גוף המטופל. | K5: מאושר
A6: CASE-004-IT-002 | B6: IT-002 | C6: משקל | D6: נוצר אוטומטית מתוצאות_מספריות. | H6: משקל 95 ק"ג. | I6: חשוב | J6: השמנה ועליית משקל עשויות להיות קשורות לאורח חיים ולאצירת נוזלים. | K6: מאושר
A7: CASE-004-IT-003 | B7: IT-003 | C7: BMI | D7: נוצר אוטומטית מתוצאות_מספריות. | H7: BMI 31.4 — השמנה. | I7: חשוב | J7: גורם סיכון נלווה שאינו לבדו מאבחן אי־ספיקת לב. | K7: מאושר
A8: CASE-004-IT-004 | B8: IT-004 | C8: סטורציה | D8: נוצר אוטומטית מתוצאות_מספריות. | H8: סטורציה 90% באוויר חדר — ירידה בריווי החמצן. | I8: חיוני במקרה | J8: חשוב לזהות חמצון ירוד ולהעריך דחיפות וניטור. | K8: מאושר
A9: CASE-004-IT-005 | B9: IT-005 | C9: קצב הלב באק״ג | D9: נוצר אוטומטית מתוצאות_מספריות. | H9: קצב 108 לדקה — טכיקרדיה סינוסלית. | I9: חיוני במקרה | J9: מצב של מצוקה ואי־ספיקת לב יכול להיות מלווה בדופק מהיר. | K9: מאושר
A10: CASE-004-IT-006 | B10: IT-006 | C10: סדירות ומקור המקצב | D10: קצב סינוס סדיר, כ־108 פעימות לדקה. | H10: קצב סינוס סדיר, כ־108 פעימות לדקה. | I10: חשוב | J10: מסייע לאבחן טכיקרדיה ולזהות הפרעת קצב. | K10: מאושר
A11: CASE-004-IT-007 | B11: IT-007 | C11: פרפור פרוזדורים והפרעות קצב אחרות | D11: לא נצפה פרפור עליות או הפרעת קצב משמעותית אחרת. | H11: לא נצפה פרפור עליות או הפרעת קצב משמעותית אחרת. | I11: חשוב | J11: הפרעות קצב עלולות לגרום להחמרה, אך אינן גורם מזוהה כאן. | K11: מאושר
A12: CASE-004-IT-008 | B12: IT-008 | C12: שינויים במקטע ST | D12: אין עליות ST חדשות או שינויי ST חריפים מובהקים. | H12: אין עליות ST חדשות או שינויי ST חריפים מובהקים. | I12: חיוני במקרה | J12: מסייע לברר אם קיים אוטם חריף; אינו שולל את כל סוגי האירוע הכלילי. | K12: מאושר
A13: CASE-004-IT-009 | B13: IT-009 | C13: גלי T, גלי Q והפרעות הולכה | D13: גלי Q פתולוגיים באזור קדמי המתאימים לאוטם ישן; אין שינוי חריף בגלי T. | H13: גלי Q פתולוגיים באזור קדמי המתאימים לאוטם ישן; אין שינוי חריף בגלי T. | I13: חשוב | J13: מכוון לנזק ישן בשריר הלב עקב אוטם קודם. | K13: מאושר
A14: CASE-004-IT-010 | B14: IT-010 | C14: גודש או בצקת ריאות | D14: צילום חזה: גודש דו־צדדי בכלי הדם הריאתיים עם סימני בצקת ריאות. | H14: צילום חזה: גודש דו־צדדי בכלי הדם הריאתיים עם סימני בצקת ריאות. | I14: חיוני במקרה | J14: תומך בהפרעה בתפקוד החדר השמאלי. | K14: מאושר
A15: CASE-004-IT-011 | B15: IT-011 | C15: גודל צל הלב | D15: צילום חזה: הגדלת צל הלב (קרדיומגליה). | H15: צילום חזה: הגדלת צל הלב (קרדיומגליה). | I15: חיוני במקרה | J15: תומך במחלת לב מבנית, אך אינו מספיק לבדו לאבחנה. | K15: מאושר
A16: CASE-004-IT-012 | B16: IT-012 | C16: תפליט פלאורלי וממצא חלופי | D16: תפליטים פלאורליים קטנים דו־צדדיים, ללא תסנין ריאתי ממוקד. | H16: תפליטים פלאורליים קטנים דו־צדדיים, ללא תסנין ריאתי ממוקד. | I16: חשוב | J16: תומך בגודש; היעדר תסנין ממוקד מפחית תמיכה בדלקת ריאות. | K16: מאושר
... A37: CASE-004-IT-033 | B37: IT-033 | C37: סטיק שתן | D37: סטיק שתן: חלבון בכמות קטנה, גלוקוז בכמות קטנה; ללא עדות לזיהום. | H37: סטיק שתן: חלבון בכמות קטנה, גלוקוז בכמות קטנה; ללא עדות לזיהום. | I37: משלים | J37: יכול להתאים לסוכרת ולפגיעה כלייתית; אינו מאבחן אי־ספיקת לב. | K37: מאושר

Sheet בדיקות_המשך
A1: תבנית בדיקות המשך
A2: כל 9 המזהים קיימים. גם בדיקה שאינה מוצדקת מקבלת תוצאה קבועה והערכת מידתיות.
A4: מזהה ערך בתיק | B4: מזהה רכיב בסיס | C4: בדיקה | D4: תוצאה קבועה | E4: זמינות | F4: השפעה על החשיבה | G4: חשיבות במקרה | H4: היגיון למשוב | I4: סטטוס
A5: CASE-004-FT-001 | B5: FT-001 | C5: אקו-קרדיוגרפיה | D5: אקו: חדר שמאל מורחב, EF 32%, ירידה גלובלית בהתכווצות ואזור קדמי עם תנועתיות מופחתת אחרי אוטם ישן; תפקוד חדר ימין ירוד במידה בינונית. ללא מחלת מסתמים קשה. | E5: לא מיידי | F5: מאשר אי־ספיקת לב עם ירידה בתפקוד חדר שמאל ומעורבות חדר ימין. | G5: חיוני במקרה | H5: זו בדיקת הבחירה להגדרת תפקוד חדרי הלב ומקטע הפליטה. | I5: מאושר
A6: CASE-004-FT-002 | B6: FT-002 | C6: הולטר אק״ג | D6: הולטר לאחר התייצבות: קצב סינוס ברוב הזמן, פעימות מוקדמות בודדות, ללא פרפור עליות ממושך. | E6: לא מיידי | F6: לא מזוהה גורם קצבי עיקרי להחמרה. | G6: משלים | H6: שימושי בחשד להפרעת קצב, אך אינו קודם לאקו ולטיפול בגודש. | I6: מאושר
A7: CASE-004-FT-003 | B7: FT-003 | C7: מבחן מאמץ | D7: רק לאחר התייצבות: התעייפות וקוצר נשימה במאמץ קל; מבחן שהופסק מוקדם, ללא שינויי ST חדשים, עם סימני אוטם ישן באק״ג הבסיסי. הבדיקה אינה אבחנתית לשלילת איסכמיה. | E7: לא מיידי | F7: מעיד על כושר מאמץ ירוד, אינו שולל איסכמיה בגלל עומס לא מספק. | G7: בדרך כלל לא מרכזי | H7: אסור לבצע ארגומטריה בשלב ההחמרה החריפה עם מצוקה נשימתית; יש לייצב תחילה. | I7: מאושר
A8: CASE-004-FT-004 | B8: FT-004 | C8: מיפוי לב במאמץ | D8: רק לאחר התייצבות וכשיש התוויה: במיפוי פגם קליטה קבוע באזור קדמי התואם צלקת מאוטם ישן, ללא עדות לאיסכמיה הפיכה משמעותית. | E8: לא מיידי | F8: תומך בנזק איסכמי ישן, ללא ממצא ברור לחסימה פעילה חדשה. | G8: משלים | H8: מיפוי אינו בדיקת קו ראשון לאבחנת אי־ספיקת לב חריפה; מתאים להערכת איסכמיה לאחר ייצוב. | I8: מאושר
A9: CASE-004-FT-005 | B9: FT-005 | C9: CT אנגיוגרפיה של העורקים הכליליים | D9: CT אנגיוגרפיה כלילית לאחר ייצוב: שינויים טרשתיים קלים עד בינוניים; הערכת אזור התומכן מוגבלת במידת מה. | E9: לא מיידי | F9: אין עדות חד־משמעית לחסימה קשה חדשה, אך הבדיקה אינה נדרשת כעת. | G9: בדרך כלל לא מרכזי | H9: בחולה עם תומכן ותפקוד כלייתי ירוד מעט, הבדיקה פחות מועילה כבירור ראשון ויש לשקול חומר ניגוד. | I9: מאושר
A10: CASE-004-FT-006 | B10: FT-006 | C10: CT חזה או אאורטה | D10: CT חזה לאחר ייצוב אם יידרש: לב מוגדל, גודש ריאתי ותפליטים קטנים, ללא ממצא חלופי משמעותי. | E10: לא מיידי | F10: אינו מוסיף מידע משמעותי מעבר לצילום החזה ולאקו במקרה הזה. | G10: בדרך כלל לא מרכזי | H10: לא נדרשת קרינה וחומר ניגוד ללא חשד ממוקד למחלה חלופית. | I10: מאושר
A11: CASE-004-FT-007 | B11: FT-007 | C11: MRI לב | D11: MRI לב לאחר ייצוב: צלקת קדמית בשריר הלב המתאימה לאוטם ישן, ותפקוד התכווצות ירוד של חדר שמאל. | E11: לא מיידי | F11: יכול לתאר נזק וצלקת, אך אינו מחליף אקו בבירור הראשוני. | G11: משלים | H11: בדיקה מתקדמת למצבים נבחרים, לא דחופה בשלב הנוכחי. | I11: מאושר
A12: CASE-004-FT-008 | B12: FT-008 | C12: אנגיוגרפיה כלילית בצנתור אבחנתי | D12: צנתור אבחנתי אם יוחלט עליו לאחר ייצוב: תומכן כלילי מהאוטם הישן פתוח; טרשת והיצרויות קלות עד בינוניות ללא חסימה משמעותית חדשה. | E12: לא מיידי | F12: תומך במחלה כלילית ישנה, ללא צורך ברור בצנתור טיפולי מיידי לפי הממצאים המדומים. | G12: משלים | H12: פולשני, ויש לשקול סיכון לחומר ניגוד; אינו נדרש בדחיפות ללא חשד לאירוע כלילי חריף. | I12: מאושר
A13: CASE-004-FT-009 | B13: FT-009 | C13: US בטן או כליות | D13: US בטן/כליות אם מבוצע: גודש ורידי כבדי קל, מבנה כליות שמור, ללא חסימת דרכי שתן. | E13: לא מיידי | F13: יכול לסייע בבירור פגיעה כלייתית או גודש כבדי, אך אינו מאבחן אי־ספיקת לב. | G13: משלים | H13: בדיקת עזר בהתאם לממצאים, אינה קודמת לבירור הלבבי. | I13: מאושר

Sheet החלטות_וטיפול
A1: תבנית החלטות וטיפול
A2: אפשר להוסיף שורות, אך יש לשמור על מזהים ייחודיים ועל מבנה העמודות.
A4: מזהה | B4: שלב | C4: פעולה או אפשרות | D4: מעמד במקרה | E4: היגיון צפוי
A5: DEC-001 | B5: אבחנה מבדלת | C5: אי־ספיקת לב דו־צדדית עם החמרה חריפה ואבחון ראשון של HFrEF | D5: אבחנה מובילה | E5: גודש ריאתי וגודש מערכתי, EF 32%, פגיעה בתפקוד החדרים ורקע של אוטם קודם.
A6: DEC-002 | B6: אבחנה מבדלת | C6: דלקת ריאות, החמרת COPD או תסמונת כלילית חריפה — כאבחנות מבדלות לקוצר נשימה | D6: חלופה סבירה פחות | E6: היעדר חום/תסנין ממוקד/צפצופים בולטים ובלי שינויי ST חריפים; עדיין בודקים תלונות וטרופונין לפי הצורך.
A7: SAFE-001 | B7: החלטה או בטיחות | C7: הערכה דחופה ואשפוז; ניטור סטורציה, נשימות, דופק ולחץ דם, הערכת זילוח ומתן חמצן לפי צורך בהיפוקסמיה | D7: חיוני במקרה | E7: סטורציה 90%, נשימה מהירה וגודש מחייבים טיפול וניטור, גם בהיעדר הלם.
A8: TRT-001 | B8: טיפול | C8: טיפול בגודש במשתנים לפי ההערכה הקלינית; לאחר התייצבות המשך/התאמה של מעכב ACE וחוסם בטא בהתאם ללחץ דם ותפקוד כליות, לצד טיפול בגורמי סיכון | D8: חיוני במקרה | E8: להקל על עומס הנוזלים תחילה; לא להתחיל או להגביר חוסם בטא בזמן חוסר יציבות או גודש חריף משמעותי.
A9: FU-001 | B9: מעקב | C9: מעקב משקל, בצקות, קוצר נשימה, לחץ דם, כליות ואלקטרוליטים, היענות לטיפול, הפחתת מלח, הפסקת עישון ומעקב קרדיולוגי | D9: חשוב | E9: מעקב והתמדה בטיפול חשובים למניעת החמרות חוזרות. דיגוקסין והשתלה אינם בחירות שגרתיות בשלב זה.

Sheet כללי_משוב
A1: תבנית כללי משוב ושיחה
A2: המשוב איכותני ומבוסס תוכן קליני, מידתיות ותקשורת.
A4: מזהה | B4: תחום | C4: סוג כלל | D4: הנחיה למערכת
A5: FB-001 | B5: אנמנזה | C5: מה נעשה היטב | D5: לשבח בירור של קוצר נשימה בשכיבה ושל מספר הכריות: אלה רמזים מרכזיים לגודש ריאתי.
A6: FB-002 | B6: אנמנזה | C6: לשקול בשנית האם היה חשוב | D6: לא כל פרט משפחתי או תעסוקתי חיוני לאבחנה המיידית; חשוב לשאול באופן ממוקד בלי לזלזל במטופל.
A7: FB-003 | B7: אנמנזה | C7: דברים שחשוב היה שתחשבו עליהם | D7: לשאול האם הוא מתעורר בלילה בתחושת מחנק, ואם הקלה מתרחשת בישיבה.
A8: FB-004 | B8: בדיקה גופנית | C8: מה נעשה היטב | D8: לשבח בירור על בצקות ברגליים, נפיחות בטנית ועלייה במשקל כעדות לגודש מערכתי.
A9: FB-005 | B9: בדיקה גופנית | C9: לשקול בשנית האם היה חשוב | D9: אין לייחס את הבצקות רק לדליות שטחיות; לבדוק גם גודש ורידי צוואר וכבד.
A10: FB-006 | B10: בדיקה גופנית | C10: דברים שחשוב היה שתחשבו עליהם | D10: לחבר בין חרחורים בריאות לבין פגיעה בתפקוד חדר שמאל ובין בצקות לבין פגיעה בצד הימני.
A11: FB-007 | B11: בדיקות מיידיות | C11: מה נעשה היטב | D11: לשבח זיהוי אוטם קודם וצנתור עם תומכן כגורם אפשרי לנזק כרוני בשריר הלב.
A12: FB-008 | B12: בדיקות מיידיות | C12: לשקול בשנית האם היה חשוב | D12: אין להסיק שאי־נטילת אספירין כשלעצמה גורמת במישרין להצטברות הנוזלים.
A13: FB-009 | B13: בדיקות מיידיות | C13: דברים שחשוב היה שתחשבו עליהם | D13: לברר אילו תרופות המטופל אכן נוטל בפועל, ולא רק מה רשום לו.
A14: FB-010 | B14: בדיקות המשך | C14: מה נעשה היטב | D14: לשבח בקשת מדדים חיוניים, בעיקר סטורציה, נשימות, דופק ולחץ דם.
A15: FB-011 | B15: בדיקות המשך | C15: לשקול בשנית האם היה חשוב | D15: אין להתעלם מסטורציה 90% ומקוצר נשימה משמעותי, גם כשאין כאב בחזה.
... A31: DIA-004 | B31: שיחה | C31: שאלה רחוקה קלינית | D31: אפשר לבקש מן התלמיד להסביר מדוע היא חשובה לפני מענה נוסף.

Sheet מילון_מזהים
A1: מילון מזהי הבסיס לבקרת איכות
A2: גיליון עזר שנבנה ממסד הידע הכללי. כל מזהה נספר מול תיק המטופל בנוסחה נפרדת; אין לערוך גיליון זה.
A4: AN — מזהה צפוי | B4: מופעים בתיק | C4: מצב | D4: PE — מזהה צפוי | E4: מופעים בתיק | F4: מצב | G4: IT — מזהה צפוי | H4: מופעים בתיק | I4: מצב | J4: FT — מזהה צפוי | K4: מופעים בתיק | L4: מצב
A5: AN-001 | B5: =COUNTIF('אנמנזה'!$B$5:$B$93,A5) | C5: =IF(B5=1,"תקין",IF(B5=0,"חסר","כפול")) | D5: PE-001 | E5: =COUNTIF('בדיקה_גופנית'!$B$5:$B$49,D5) | F5: =IF(E5=1,"תקין",IF(E5=0,"חסר","כפול")) | G5: IT-001 | H5: =COUNTIF('בדיקות_מיידיות'!$B$5:$B$37,G5) | I5: =IF(H5=1,"תקין",IF(H5=0,"חסר","כפול")) | J5: FT-001 | K5: =COUNTIF('בדיקות_המשך'!$B$5:$B$13,J5) | L5: =IF(K5=1,"תקין",IF(K5=0,"חסר","כפול"))
A6: AN-002 | B6: =COUNTIF('אנמנזה'!$B$5:$B$93,A6) | C6: =IF(B6=1,"תקין",IF(B6=0,"חסר","כפול")) | D6: PE-002 | E6: =COUNTIF('בדיקה_גופנית'!$B$5:$B$49,D6) | F6: =IF(E6=1,"תקין",IF(E6=0,"חסר","כפול")) | G6: IT-002 | H6: =COUNTIF('בדיקות_מיידיות'!$B$5:$B$37,G6) | I6: =IF(H6=1,"תקין",IF(H6=0,"חסר","כפול")) | J6: FT-002 | K6: =COUNTIF('בדיקות_המשך'!$B$5:$B$13,J6) | L6: =IF(K6=1,"תקין",IF(K6=0,"חסר","כפול"))
A7: AN-003 | B7: =COUNTIF('אנמנזה'!$B$5:$B$93,A7) | C7: =IF(B7=1,"תקין",IF(B7=0,"חסר","כפול")) | D7: PE-003 | E7: =COUNTIF('בדיקה_גופנית'!$B$5:$B$49,D7) | F7: =IF(E7=1,"תקין",IF(E7=0,"חסר","כפול")) | G7: IT-003 | H7: =COUNTIF('בדיקות_מיידיות'!$B$5:$B$37,G7) | I7: =IF(H7=1,"תקין",IF(H7=0,"חסר","כפול")) | J7: FT-003 | K7: =COUNTIF('בדיקות_המשך'!$B$5:$B$13,J7) | L7: =IF(K7=1,"תקין",IF(K7=0,"חסר","כפול"))
A8: AN-004 | B8: =COUNTIF('אנמנזה'!$B$5:$B$93,A8) | C8: =IF(B8=1,"תקין",IF(B8=0,"חסר","כפול")) | D8: PE-004 | E8: =COUNTIF('בדיקה_גופנית'!$B$5:$B$49,D8) | F8: =IF(E8=1,"תקין",IF(E8=0,"חסר","כפול")) | G8: IT-004 | H8: =COUNTIF('בדיקות_מיידיות'!$B$5:$B$37,G8) | I8: =IF(H8=1,"תקין",IF(H8=0,"חסר","כפול")) | J8: FT-004 | K8: =COUNTIF('בדיקות_המשך'!$B$5:$B$13,J8) | L8: =IF(K8=1,"תקין",IF(K8=0,"חסר","כפול"))
A9: AN-005 | B9: =COUNTIF('אנמנזה'!$B$5:$B$93,A9) | C9: =IF(B9=1,"תקין",IF(B9=0,"חסר","כפול")) | D9: PE-005 | E9: =COUNTIF('בדיקה_גופנית'!$B$5:$B$49,D9) | F9: =IF(E9=1,"תקין",IF(E9=0,"חסר","כפול")) | G9: IT-005 | H9: =COUNTIF('בדיקות_מיידיות'!$B$5:$B$37,G9) | I9: =IF(H9=1,"תקין",IF(H9=0,"חסר","כפול")) | J9: FT-005 | K9: =COUNTIF('בדיקות_המשך'!$B$5:$B$13,J9) | L9: =IF(K9=1,"תקין",IF(K9=0,"חסר","כפול"))
A10: AN-006 | B10: =COUNTIF('אנמנזה'!$B$5:$B$93,A10) | C10: =IF(B10=1,"תקין",IF(B10=0,"חסר","כפול")) | D10: PE-006 | E10: =COUNTIF('בדיקה_גופנית'!$B$5:$B$49,D10) | F10: =IF(E10=1,"תקין",IF(E10=0,"חסר","כפול")) | G10: IT-006 | H10: =COUNTIF('בדיקות_מיידיות'!$B$5:$B$37,G10) | I10: =IF(H10=1,"תקין",IF(H10=0,"חסר","כפול")) | J10: FT-006 | K10: =COUNTIF('בדיקות_המשך'!$B$5:$B$13,J10) | L10: =IF(K10=1,"תקין",IF(K10=0,"חסר","כפול"))
A11: AN-007 | B11: =COUNTIF('אנמנזה'!$B$5:$B$93,A11) | C11: =IF(B11=1,"תקין",IF(B11=0,"חסר","כפול")) | D11: PE-007 | E11: =COUNTIF('בדיקה_גופנית'!$B$5:$B$49,D11) | F11: =IF(E11=1,"תקין",IF(E11=0,"חסר","כפול")) | G11: IT-007 | H11: =COUNTIF('בדיקות_מיידיות'!$B$5:$B$37,G11) | I11: =IF(H11=1,"תקין",IF(H11=0,"חסר","כפול")) | J11: FT-007 | K11: =COUNTIF('בדיקות_המשך'!$B$5:$B$13,J11) | L11: =IF(K11=1,"תקין",IF(K11=0,"חסר","כפול"))
A12: AN-008 | B12: =COUNTIF('אנמנזה'!$B$5:$B$93,A12) | C12: =IF(B12=1,"תקין",IF(B12=0,"חסר","כפול")) | D12: PE-008 | E12: =COUNTIF('בדיקה_גופנית'!$B$5:$B$49,D12) | F12: =IF(E12=1,"תקין",IF(E12=0,"חסר","כפול")) | G12: IT-008 | H12: =COUNTIF('בדיקות_מיידיות'!$B$5:$B$37,G12) | I12: =IF(H12=1,"תקין",IF(H12=0,"חסר","כפול")) | J12: FT-008 | K12: =COUNTIF('בדיקות_המשך'!$B$5:$B$13,J12) | L12: =IF(K12=1,"תקין",IF(K12=0,"חסר","כפול"))
A13: AN-009 | B13: =COUNTIF('אנמנזה'!$B$5:$B$93,A13) | C13: =IF(B13=1,"תקין",IF(B13=0,"חסר","כפול")) | D13: PE-009 | E13: =COUNTIF('בדיקה_גופנית'!$B$5:$B$49,D13) | F13: =IF(E13=1,"תקין",IF(E13=0,"חסר","כפול")) | G13: IT-009 | H13: =COUNTIF('בדיקות_מיידיות'!$B$5:$B$37,G13) | I13: =IF(H13=1,"תקין",IF(H13=0,"חסר","כפול")) | J13: FT-009 | K13: =COUNTIF('בדיקות_המשך'!$B$5:$B$13,J13) | L13: =IF(K13=1,"תקין",IF(K13=0,"חסר","כפול"))
A14: AN-010 | B14: =COUNTIF('אנמנזה'!$B$5:$B$93,A14) | C14: =IF(B14=1,"תקין",IF(B14=0,"חסר","כפול")) | D14: PE-010 | E14: =COUNTIF('בדיקה_גופנית'!$B$5:$B$49,D14) | F14: =IF(E14=1,"תקין",IF(E14=0,"חסר","כפול")) | G14: IT-010 | H14: =COUNTIF('בדיקות_מיידיות'!$B$5:$B$37,G14) | I14: =IF(H14=1,"תקין",IF(H14=0,"חסר","כפול"))
A15: AN-011 | B15: =COUNTIF('אנמנזה'!$B$5:$B$93,A15) | C15: =IF(B15=1,"תקין",IF(B15=0,"חסר","כפול")) | D15: PE-011 | E15: =COUNTIF('בדיקה_גופנית'!$B$5:$B$49,D15) | F15: =IF(E15=1,"תקין",IF(E15=0,"חסר","כפול")) | G15: IT-011 | H15: =COUNTIF('בדיקות_מיידיות'!$B$5:$B$37,G15) | I15: =IF(H15=1,"תקין",IF(H15=0,"חסר","כפול"))
A16: AN-012 | B16: =COUNTIF('אנמנזה'!$B$5:$B$93,A16) | C16: =IF(B16=1,"תקין",IF(B16=0,"חסר","כפול")) | D16: PE-012 | E16: =COUNTIF('בדיקה_גופנית'!$B$5:$B$49,D16) | F16: =IF(E16=1,"תקין",IF(E16=0,"חסר","כפול")) | G16: IT-012 | H16: =COUNTIF('בדיקות_מיידיות'!$B$5:$B$37,G16) | I16: =IF(H16=1,"תקין",IF(H16=0,"חסר","כפול"))
A17: AN-013 | B17: =COUNTIF('אנמנזה'!$B$5:$B$93,A17) | C17: =IF(B17=1,"תקין",IF(B17=0,"חסר","כפול")) | D17: PE-013 | E17: =COUNTIF('בדיקה_גופנית'!$B$5:$B$49,D17) | F17: =IF(E17=1,"תקין",IF(E17=0,"חסר","כפול")) | G17: IT-013 | H17: =COUNTIF('בדיקות_מיידיות'!$B$5:$B$37,G17) | I17: =IF(H17=1,"תקין",IF(H17=0,"חסר","כפול"))
A18: AN-014 | B18: =COUNTIF('אנמנזה'!$B$5:$B$93,A18) | C18: =IF(B18=1,"תקין",IF(B18=0,"חסר","כפול")) | D18: PE-014 | E18: =COUNTIF('בדיקה_גופנית'!$B$5:$B$49,D18) | F18: =IF(E18=1,"תקין",IF(E18=0,"חסר","כפול")) | G18: IT-014 | H18: =COUNTIF('בדיקות_מיידיות'!$B$5:$B$37,G18) | I18: =IF(H18=1,"תקין",IF(H18=0,"חסר","כפול"))
A19: AN-015 | B19: =COUNTIF('אנמנזה'!$B$5:$B$93,A19) | C19: =IF(B19=1,"תקין",IF(B19=0,"חסר","כפול")) | D19: PE-015 | E19: =COUNTIF('בדיקה_גופנית'!$B$5:$B$49,D19) | F19: =IF(E19=1,"תקין",IF(E19=0,"חסר","כפול")) | G19: IT-015 | H19: =COUNTIF('בדיקות_מיידיות'!$B$5:$B$37,G19) | I19: =IF(H19=1,"תקין",IF(H19=0,"חסר","כפול"))
A20: AN-016 | B20: =COUNTIF('אנמנזה'!$B$5:$B$93,A20) | C20: =IF(B20=1,"תקין",IF(B20=0,"חסר","כפול")) | D20: PE-016 | E20: =COUNTIF('בדיקה_גופנית'!$B$5:$B$49,D20) | F20: =IF(E20=1,"תקין",IF(E20=0,"חסר","כפול")) | G20: IT-016 | H20: =COUNTIF('בדיקות_מיידיות'!$B$5:$B$37,G20) | I20: =IF(H20=1,"תקין",IF(H20=0,"חסר","כפול"))
A21: AN-017 | B21: =COUNTIF('אנמנזה'!$B$5:$B$93,A21) | C21: =IF(B21=1,"תקין",IF(B21=0,"חסר","כפול")) | D21: PE-017 | E21: =COUNTIF('בדיקה_גופנית'!$B$5:$B$49,D21) | F21: =IF(E21=1,"תקין",IF(E21=0,"חסר","כפול")) | G21: IT-017 | H21: =COUNTIF('בדיקות_מיידיות'!$B$5:$B$37,G21) | I21: =IF(H21=1,"תקין",IF(H21=0,"חסר","כפול"))
A22: AN-018 | B22: =COUNTIF('אנמנזה'!$B$5:$B$93,A22) | C22: =IF(B22=1,"תקין",IF(B22=0,"חסר","כפול")) | D22: PE-018 | E22: =COUNTIF('בדיקה_גופנית'!$B$5:$B$49,D22) | F22: =IF(E22=1,"תקין",IF(E22=0,"חסר","כפול")) | G22: IT-018 | H22: =COUNTIF('בדיקות_מיידיות'!$B$5:$B$37,G22) | I22: =IF(H22=1,"תקין",IF(H22=0,"חסר","כפול"))
A23: AN-019 | B23: =COUNTIF('אנמנזה'!$B$5:$B$93,A23) | C23: =IF(B23=1,"תקין",IF(B23=0,"חסר","כפול")) | D23: PE-019 | E23: =COUNTIF('בדיקה_גופנית'!$B$5:$B$49,D23) | F23: =IF(E23=1,"תקין",IF(E23=0,"חסר","כפול")) | G23: IT-019 | H23: =COUNTIF('בדיקות_מיידיות'!$B$5:$B$37,G23) | I23: =IF(H23=1,"תקין",IF(H23=0,"חסר","כפול"))
A24: AN-020 | B24: =COUNTIF('אנמנזה'!$B$5:$B$93,A24) | C24: =IF(B24=1,"תקין",IF(B24=0,"חסר","כפול")) | D24: PE-020 | E24: =COUNTIF('בדיקה_גופנית'!$B$5:$B$49,D24) | F24: =IF(E24=1,"תקין",IF(E24=0,"חסר","כפול")) | G24: IT-020 | H24: =COUNTIF('בדיקות_מיידיות'!$B$5:$B$37,G24) | I24: =IF(H24=1,"תקין",IF(H24=0,"חסר","כפול"))
A25: AN-021 | B25: =COUNTIF('אנמנזה'!$B$5:$B$93,A25) | C25: =IF(B25=1,"תקין",IF(B25=0,"חסר","כפול")) | D25: PE-021 | E25: =COUNTIF('בדיקה_גופנית'!$B$5:$B$49,D25) | F25: =IF(E25=1,"תקין",IF(E25=0,"חסר","כפול")) | G25: IT-021 | H25: =COUNTIF('בדיקות_מיידיות'!$B$5:$B$37,G25) | I25: =IF(H25=1,"תקין",IF(H25=0,"חסר","כפול"))
... A37: AN-033 | B37: =COUNTIF('אנמנזה'!$B$5:$B$93,A37) | C37: =IF(B37=1,"תקין",IF(B37=0,"חסר","כפול")) | D37: PE-033 | E37: =COUNTIF('בדיקה_גופנית'!$B$5:$B$49,D37) | F37: =IF(E37=1,"תקין",IF(E37=0,"חסר","כפול")) | G37: IT-033 | H37: =COUNTIF('בדיקות_מיידיות'!$B$5:$B$37,G37) | I37: =IF(H37=1,"תקין",IF(H37=0,"חסר","כפול"))
A38: AN-034 | B38: =COUNTIF('אנמנזה'!$B$5:$B$93,A38) | C38: =IF(B38=1,"תקין",IF(B38=0,"חסר","כפול")) | D38: PE-034 | E38: =COUNTIF('בדיקה_גופנית'!$B$5:$B$49,D38) | F38: =IF(E38=1,"תקין",IF(E38=0,"חסר","כפול"))
A39: AN-035 | B39: =COUNTIF('אנמנזה'!$B$5:$B$93,A39) | C39: =IF(B39=1,"תקין",IF(B39=0,"חסר","כפול")) | D39: PE-035 | E39: =COUNTIF('בדיקה_גופנית'!$B$5:$B$49,D39) | F39: =IF(E39=1,"תקין",IF(E39=0,"חסר","כפול"))
A40: AN-036 | B40: =COUNTIF('אנמנזה'!$B$5:$B$93,A40) | C40: =IF(B40=1,"תקין",IF(B40=0,"חסר","כפול")) | D40: PE-036 | E40: =COUNTIF('בדיקה_גופנית'!$B$5:$B$49,D40) | F40: =IF(E40=1,"תקין",IF(E40=0,"חסר","כפול"))
A41: AN-037 | B41: =COUNTIF('אנמנזה'!$B$5:$B$93,A41) | C41: =IF(B41=1,"תקין",IF(B41=0,"חסר","כפול")) | D41: PE-037 | E41: =COUNTIF('בדיקה_גופנית'!$B$5:$B$49,D41) | F41: =IF(E41=1,"תקין",IF(E41=0,"חסר","כפול"))
A42: AN-038 | B42: =COUNTIF('אנמנזה'!$B$5:$B$93,A42) | C42: =IF(B42=1,"תקין",IF(B42=0,"חסר","כפול")) | D42: PE-038 | E42: =COUNTIF('בדיקה_גופנית'!$B$5:$B$49,D42) | F42: =IF(E42=1,"תקין",IF(E42=0,"חסר","כפול"))
A43: AN-039 | B43: =COUNTIF('אנמנזה'!$B$5:$B$93,A43) | C43: =IF(B43=1,"תקין",IF(B43=0,"חסר","כפול")) | D43: PE-039 | E43: =COUNTIF('בדיקה_גופנית'!$B$5:$B$49,D43) | F43: =IF(E43=1,"תקין",IF(E43=0,"חסר","כפול"))
A44: AN-040 | B44: =COUNTIF('אנמנזה'!$B$5:$B$93,A44) | C44: =IF(B44=1,"תקין",IF(B44=0,"חסר","כפול")) | D44: PE-040 | E44: =COUNTIF('בדיקה_גופנית'!$B$5:$B$49,D44) | F44: =IF(E44=1,"תקין",IF(E44=0,"חסר","כפול"))
A45: AN-041 | B45: =COUNTIF('אנמנזה'!$B$5:$B$93,A45) | C45: =IF(B45=1,"תקין",IF(B45=0,"חסר","כפול")) | D45: PE-041 | E45: =COUNTIF('בדיקה_גופנית'!$B$5:$B$49,D45) | F45: =IF(E45=1,"תקין",IF(E45=0,"חסר","כפול"))
A46: AN-042 | B46: =COUNTIF('אנמנזה'!$B$5:$B$93,A46) | C46: =IF(B46=1,"תקין",IF(B46=0,"חסר","כפול")) | D46: PE-042 | E46: =COUNTIF('בדיקה_גופנית'!$B$5:$B$49,D46) | F46: =IF(E46=1,"תקין",IF(E46=0,"חסר","כפול"))
A47: AN-043 | B47: =COUNTIF('אנמנזה'!$B$5:$B$93,A47) | C47: =IF(B47=1,"תקין",IF(B47=0,"חסר","כפול")) | D47: PE-043 | E47: =COUNTIF('בדיקה_גופנית'!$B$5:$B$49,D47) | F47: =IF(E47=1,"תקין",IF(E47=0,"חסר","כפול"))
A48: AN-044 | B48: =COUNTIF('אנמנזה'!$B$5:$B$93,A48) | C48: =IF(B48=1,"תקין",IF(B48=0,"חסר","כפול")) | D48: PE-044 | E48: =COUNTIF('בדיקה_גופנית'!$B$5:$B$49,D48) | F48: =IF(E48=1,"תקין",IF(E48=0,"חסר","כפול"))
A49: AN-045 | B49: =COUNTIF('אנמנזה'!$B$5:$B$93,A49) | C49: =IF(B49=1,"תקין",IF(B49=0,"חסר","כפול")) | D49: PE-045 | E49: =COUNTIF('בדיקה_גופנית'!$B$5:$B$49,D49) | F49: =IF(E49=1,"תקין",IF(E49=0,"חסר","כפול"))
A50: AN-046 | B50: =COUNTIF('אנמנזה'!$B$5:$B$93,A50) | C50: =IF(B50=1,"תקין",IF(B50=0,"חסר","כפול"))
A51: AN-047 | B51: =COUNTIF('אנמנזה'!$B$5:$B$93,A51) | C51: =IF(B51=1,"תקין",IF(B51=0,"חסר","כפול"))
A52: AN-048 | B52: =COUNTIF('אנמנזה'!$B$5:$B$93,A52) | C52: =IF(B52=1,"תקין",IF(B52=0,"חסר","כפול"))
...

Sheet בקרת_איכות
A1: בקרת איכות אוטומטית
A2: בדיקות מבנה, שיוך מזהים, מקור אמת יחיד לערכים מספריים והשלמת פרסונה.
A4: תחום | B4: צפוי | C4: מזהים בפועל | D4: מזהים כפולים | E4: מזהים זרים | F4: מזהים חסרים | G4: שורות טיוטה/חסרות | H4: סטטוס מבנה
A5: אנמנזה | B5: 89 | C5: =COUNTA('אנמנזה'!$B$5:$B$93) | D5: =SUMPRODUCT(--(COUNTIF('אנמנזה'!$B$5:$B$93,'אנמנזה'!$B$5:$B$93)>1)) | E5: =MAX(0,C5-SUM('מילון_מזהים'!$B$5:$B$93)) | F5: =COUNTIF('מילון_מזהים'!$B$5:$B$93,0) | G5: =COUNTIF('אנמנזה'!$G$5:$G$93,"טיוטה") | H5: =IF(AND(C5=B5,D5=0,E5=0,F5=0),"תקין","דורש בדיקה")
A6: בדיקה גופנית | B6: 45 | C6: =COUNTA('בדיקה_גופנית'!$B$5:$B$49) | D6: =SUMPRODUCT(--(COUNTIF('בדיקה_גופנית'!$B$5:$B$49,'בדיקה_גופנית'!$B$5:$B$49)>1)) | E6: =MAX(0,C6-SUM('מילון_מזהים'!$E$5:$E$49)) | F6: =COUNTIF('מילון_מזהים'!$E$5:$E$49,0) | G6: =COUNTIF('בדיקה_גופנית'!$G$5:$G$49,"טיוטה") | H6: =IF(AND(C6=B6,D6=0,E6=0,F6=0),"תקין","דורש בדיקה")
A7: בדיקות מיידיות | B7: 33 | C7: =COUNTA('בדיקות_מיידיות'!$B$5:$B$37) | D7: =SUMPRODUCT(--(COUNTIF('בדיקות_מיידיות'!$B$5:$B$37,'בדיקות_מיידיות'!$B$5:$B$37)>1)) | E7: =MAX(0,C7-SUM('מילון_מזהים'!$H$5:$H$37)) | F7: =COUNTIF('מילון_מזהים'!$H$5:$H$37,0) | G7: =COUNTIF('בדיקות_מיידיות'!$K$5:$K$37,"טיוטה") | H7: =IF(AND(C7=B7,D7=0,E7=0,F7=0),"תקין","דורש בדיקה")
A8: בדיקות המשך | B8: 9 | C8: =COUNTA('בדיקות_המשך'!$B$5:$B$13) | D8: =SUMPRODUCT(--(COUNTIF('בדיקות_המשך'!$B$5:$B$13,'בדיקות_המשך'!$B$5:$B$13)>1)) | E8: =MAX(0,C8-SUM('מילון_מזהים'!$K$5:$K$13)) | F8: =COUNTIF('מילון_מזהים'!$K$5:$K$13,0) | G8: =COUNTIF('בדיקות_המשך'!$I$5:$I$13,"טיוטה") | H8: =IF(AND(C8=B8,D8=0,E8=0,F8=0),"תקין","דורש בדיקה")
A9: מדדים מספריים | B9: 32 | C9: =COUNTA('תוצאות_מספריות'!$A$5:$A$36) | D9: =SUMPRODUCT(--(COUNTIF('תוצאות_מספריות'!$A$5:$A$36,'תוצאות_מספריות'!$A$5:$A$36)>1)) | E9: =MAX(0,C9-SUM('מדדים_מספריים'!$G$5:$G$36)) | F9: =COUNTIF('מדדים_מספריים'!$G$5:$G$36,0) | G9: =COUNTIF('תוצאות_מספריות'!$I$5:$I$36,"טיוטה") | H9: =IF(AND(C9=B9,D9=0,E9=0,F9=0),"תקין","דורש בדיקה")
A11: בדיקת תוכן | B11: כלל
A12: מענה סמנטי | B12: המערכת מסתמכת על משמעות השאלה, לא על התאמת מילות מפתח.
A13: מענה ממוקד | B13: המטופל אינו מנדב מידע שלא נשאל עליו.
A14: טווחי ייחוס | B14: לכל בדיקת דם מספרית יש ערך, יחידה וטווח ייחוס.
A15: בדיקה קלינית | B15: לאחר השלמה אוטומטית נדרשת בדיקת עקביות ידנית מול הסיפור והרובריקות.
A16: שיוך מדד–בדיקה | B16: 0 | C16: =COUNTIF('מדדים_מספריים'!$H$5:$H$36,0) | H16: =IF(C16=B16,"תקין","דורש בדיקה")
A17: כפילות מקור מספרי | B17: 0 | C17: =COUNTA('בדיקות_מיידיות'!$E$5:$G$37) | H17: =IF(C17=B17,"תקין","דורש בדיקה")
A18: פרסונה קצרה | B18: 1 | C18: =COUNTIF('מטא_מקרה'!$A$5:$A$30,"פרסונה קצרה") | H18: =IF(C18=B18,"תקין","דורש בדיקה")

Sheet תוצאות_מספריות
A1: תבנית תוצאות מספריות
A2: זהו מקור האמת היחיד לערכי מטופל מספריים, יחידות וטווחי ייחוס. כל שורת מדד מכילה ערך אחד.
A4: מזהה מדד | B4: מזהה בדיקה | C4: שם המדד | D4: ערך | E4: יחידה | F4: טווח ייחוס | G4: פרשנות במקרה | H4: חובת הצגה | I4: סטטוס
A5: IT-001-HGT | B5: IT-001 | C5: גובה | D5: 174 | E5: cm | F5: לא חל | G5: גובה המטופל. | H5: לא | I5: מאושר
A6: IT-002-WGT | B6: IT-002 | C6: משקל | D6: 95 | E6: kg | F6: לא חל | G6: השמנה; יש לעקוב אחר שינויים במשקל ונוזלים. | H6: לא | I6: מאושר
A7: IT-003-BMI | B7: IT-003 | C7: BMI | D7: 31.4 | E7: kg/m² | F7: 18.5–24.9 | G7: השמנה מדרגה ראשונה. | H7: לא | I7: מאושר
A8: IT-004-SPO2 | B8: IT-004 | C8: סטורציה | D8: 90 | E8: % | F8: 95–100 | G8: ירידה בריווי החמצן באוויר חדר; מצדיק הערכה וטיפול דחופים. | H8: כן | I8: מאושר
A9: IT-005-HR | B9: IT-005 | C9: קצב לב באק״ג | D9: 108 | E9: פעימות/דקה | F9: 60–100 | G9: טכיקרדיה סינוסלית. | H9: כן | I9: מאושר
A10: IT-013-HB | B10: IT-013 | C10: המוגלובין | D10: 13.8 | E10: g/dL | F10: 13.5–17.5 | G10: המוגלובין בתחום התקין לגבר. | H10: כן | I10: מאושר
A11: IT-013-HCT | B11: IT-013 | C11: המטוקריט | D11: 41 | E11: % | F11: 41–53 | G11: המטוקריט בטווח התקין. | H11: כן | I11: מאושר
A12: IT-014-WBC | B12: IT-014 | C12: תאי דם לבנים | D12: 7.8 | E12: 10³/µL | F12: 4–11 | G12: אין לויקוציטוזיס התומכת בזיהום משמעותי. | H12: כן | I12: מאושר
A13: IT-015-PLT | B13: IT-015 | C13: טסיות | D13: 235 | E13: 10³/µL | F13: 150–450 | G13: טסיות תקינות. | H13: כן | I13: מאושר
A14: IT-016-GLU | B14: IT-016 | C14: גלוקוז | D14: 155 | E14: mg/dL | F14: 70–99 בצום | G14: סוכר גבוה; מצב צום לא הוגדר. | H14: כן | I14: מאושר
A15: IT-017-HBA1C | B15: IT-017 | C15: HbA1c | D15: 7.5 | E15: % | F15: מתחת 5.7 באדם ללא סוכרת | G15: איזון סוכרת אינו מיטבי. | H15: כן | I15: מאושר
... A36: IT-032-BNP | B36: IT-032 | C36: BNP | D36: לא נבדק | E36: pg/mL | F36: לא מיועד להוראה | G36: המורה החליט שלא לכלול בדיקת BNP; שדה קיים בתבנית אך אינו אמור להופיע לתלמיד. | H36: כן | I36: מאושר

Sheet מדדים_מספריים
A1: מדדים מספריים ותוצאות מרובות
A2: הגדרות מדדים בלבד. הערכים עצמם נשמרים בתוצאות_מספריות; עמודות הבקרה מוודאות מופע יחיד ושיוך נכון לבדיקה.
A4: מזהה מדד | B4: מזהה בדיקה | C4: שם המדד | D4: יחידה מקובלת | E4: חובת טווח בתיק | F4: כלל הצגה | G4: מופעים בתיק | H4: שיוך תקין
A5: IT-001-HGT | B5: IT-001 | C5: גובה | D5: cm | E5: לא | F5: מדידה; אין טווח מעבדתי | G5: =COUNTIF('תוצאות_מספריות'!$A$5:$A$36,A5) | H5: =IF(LEFT(A5,6)=B5,1,0)
A6: IT-002-WGT | B6: IT-002 | C6: משקל | D6: kg | E6: לא | F6: מדידה; אין טווח מעבדתי | G6: =COUNTIF('תוצאות_מספריות'!$A$5:$A$36,A6) | H6: =IF(LEFT(A6,6)=B6,1,0)
A7: IT-003-BMI | B7: IT-003 | C7: BMI | D7: kg/m² | E7: לא | F7: פרשנות לפי טווחי BMI | G7: =COUNTIF('תוצאות_מספריות'!$A$5:$A$36,A7) | H7: =IF(LEFT(A7,6)=B7,1,0)
A8: IT-004-SPO2 | B8: IT-004 | C8: סטורציה | D8: % | E8: כן | F8: להציג טווח תקין לצד התוצאה | G8: =COUNTIF('תוצאות_מספריות'!$A$5:$A$36,A8) | H8: =IF(LEFT(A8,6)=B8,1,0)
A9: IT-005-HR | B9: IT-005 | C9: קצב לב באק״ג | D9: פעימות/דקה | E9: כן | F9: להציג טווח תקין לצד התוצאה | G9: =COUNTIF('תוצאות_מספריות'!$A$5:$A$36,A9) | H9: =IF(LEFT(A9,6)=B9,1,0)
A10: IT-013-HB | B10: IT-013 | C10: המוגלובין | D10: g/dL | E10: כן | F10: טווח ייחוס תלוי מעבדה ומין | G10: =COUNTIF('תוצאות_מספריות'!$A$5:$A$36,A10) | H10: =IF(LEFT(A10,6)=B10,1,0)
A11: IT-013-HCT | B11: IT-013 | C11: המטוקריט | D11: % | E11: כן | F11: טווח ייחוס תלוי מעבדה ומין | G11: =COUNTIF('תוצאות_מספריות'!$A$5:$A$36,A11) | H11: =IF(LEFT(A11,6)=B11,1,0)
A12: IT-014-WBC | B12: IT-014 | C12: תאי דם לבנים | D12: 10³/µL | E12: כן | F12: טווח ייחוס של המעבדה | G12: =COUNTIF('תוצאות_מספריות'!$A$5:$A$36,A12) | H12: =IF(LEFT(A12,6)=B12,1,0)
A13: IT-015-PLT | B13: IT-015 | C13: טסיות | D13: 10³/µL | E13: כן | F13: טווח ייחוס של המעבדה | G13: =COUNTIF('תוצאות_מספריות'!$A$5:$A$36,A13) | H13: =IF(LEFT(A13,6)=B13,1,0)
A14: IT-016-GLU | B14: IT-016 | C14: גלוקוז | D14: mg/dL | E14: כן | F14: לציין אם בצום | G14: =COUNTIF('תוצאות_מספריות'!$A$5:$A$36,A14) | H14: =IF(LEFT(A14,6)=B14,1,0)
A15: IT-017-HBA1C | B15: IT-017 | C15: HbA1c | D15: % | E15: כן | F15: טווח ייחוס של המעבדה | G15: =COUNTIF('תוצאות_מספריות'!$A$5:$A$36,A15) | H15: =IF(LEFT(A15,6)=B15,1,0)
A16: IT-018-TC | B16: IT-018 | C16: כולסטרול כללי | D16: mg/dL | E16: כן | F16: להציג יעד/טווח מעבדה | G16: =COUNTIF('תוצאות_מספריות'!$A$5:$A$36,A16) | H16: =IF(LEFT(A16,6)=B16,1,0)
... A36: IT-032-BNP | B36: IT-032 | C36: BNP | D36: pg/mL | E36: כן | F36: טווח ייחוס של המעבדה | G36: =COUNTIF('תוצאות_מספריות'!$A$5:$A$36,A36) | H36: =IF(LEFT(A36,6)=B36,1,0)
